<?xml version="1.0"?>
<robot name="Bilkins">


  <link name="chassis">
    <visual>
      <geometry>
        <mesh filename="package://bilkins/meshes/chassis.dae" scale="0.1 0.1 0.1" />
      </geometry>
      <origin rpy="0.0 0 0" xyz="0 0 0"/>
    </visual>
    <collision>
      <geometry>
        <mesh filename="package://bilkins/meshes/chassis.dae" scale="0.1 0.1 0.1" />
      </geometry>
      <origin rpy="0.0 0 0" xyz="0 0 0"/>
    </collision>
    <inertial>
      <mass value="0.2" />
      <inertia ixx="0.4" ixy="0.0" ixz="0.0" iyy="0.4" iyz="0.0" izz="0.2"/>
    </inertial>
  </link>

  <link name="rear_axle">
    <visual>
      <geometry>
        <mesh filename="package://bilkins/meshes/rear_axle.dae" scale="0.1 0.1 0.1" />
      </geometry>
      <origin xyz="-1.3 0 -0.5" />
    </visual>
    <collision>
      <geometry>
        <mesh filename="package://bilkins/meshes/rear_axle.dae" scale="0.1 0.1 0.1" />
      </geometry>
      <origin xyz="-1.3 0 -0.5" />
    </collision>
    <inertial>
      <mass value="0.14" />
      <inertia ixx="0.4" ixy="0.0" ixz="0.0" iyy="0.4" iyz="0.0" izz="0.2"/>
    </inertial>
  </link>

  <link name="front_axle">
    <visual>
      <geometry>
        <mesh filename="package://bilkins/meshes/front_axle.dae" scale="0.1 0.1 0.1" />
      </geometry>
      <origin xyz="1.3 0 -0.5" />
    </visual>
    <collision>
      <geometry>
        <mesh filename="package://bilkins/meshes/front_axle.dae" scale="0.1 0.1 0.1" />
      </geometry>
      <origin xyz="1.3 0 -0.5" />
    </collision>
    <inertial>
      <mass value="0.1" />
      <inertia ixx="0.4" ixy="0.0" ixz="0.0" iyy="0.4" iyz="0.0" izz="0.2"/>
    </inertial>
  </link>

  <link name="front_left_wheel">
    <visual>
      <geometry>
        <mesh filename="package://bilkins/meshes/front_left_wheel.dae" scale="0.1 0.1 0.1" />
      </geometry>
      <origin xyz="1.3 0.9 -0.5" />
    </visual>
    <collision>
      <geometry>
        <mesh filename="package://bilkins/meshes/front_left_wheel.dae" scale="0.1 0.1 0.1" />
      </geometry>
      <origin xyz="1.3 0.9 -0.5" />
    </collision>
    <inertial>
      <mass value="0.02" />
      <inertia ixx="0.4" ixy="0.0" ixz="0.0" iyy="0.4" iyz="0.0" izz="0.2"/>
    </inertial>
  </link>

  <link name="front_right_wheel">
    <visual>
      <geometry>
        <mesh filename="package://bilkins/meshes/front_right_wheel.dae" scale="0.1 0.1 0.1" />
      </geometry>
      <origin xyz="1.3 -0.9 -0.5" />
    </visual>
    <collision>
      <geometry>
        <mesh filename="package://bilkins/meshes/front_right_wheel.dae" scale="0.1 0.1 0.1" />
      </geometry>
      <origin xyz="1.3 -0.9 -0.5" />
    </collision>
    <inertial>
      <mass value="0.02" />
      <inertia ixx="0.4" ixy="0.0" ixz="0.0" iyy="0.4" iyz="0.0" izz="0.2"/>
    </inertial>
  </link>

  <joint name="rear_axle_to_chassis" type="continuous">
    <parent link="chassis"/>
    <child link="rear_axle" />
    <axis xyz="0 1 0" />
    <origin xyz="1.3 0 0.5" />
  </joint>

  <joint name="front_axle_to_chassis" type="revolute">
    <axis xyz="0 0 1" />
    <limit effort="1000.0" lower="-0.1" upper="0.1" velocity="0.5"/>
    <parent link="chassis"/>
    <child link="front_axle" />
    <origin xyz="-1.3 0 0.5" />
  </joint>

  <joint name="front_left_wheel_to_axle" type="continuous">
    <parent link="front_axle"/>
    <child link="front_left_wheel" />
    <axis xyz="0 1 0" />
    <origin xyz="0 -0.9 0" />
  </joint>

  <joint name="front_right_wheel_to_axle" type="continuous">
    <parent link="front_axle"/>
    <child link="front_right_wheel" />
    <axis xyz="0 1 0" />
    <origin xyz="0 0.9 0" />
  </joint>

  <joint name="hokuyo_joint" type="fixed">
    <axis xyz="0 1 0" />
    <origin xyz="0 0 0" rpy="0 0 0"/>
    <parent link="chassis"/>
    <child link="hokuyo_link"/>
  </joint>

  <!-- Hokuyo Laser -->
  <link name="hokuyo_link">
    <collision>
      <origin xyz="2 0 0" rpy="0 0 0"/>
      <geometry>
	<box size="1 1 1"/>
      </geometry>
    </collision>

    <visual>
      <origin xyz="0 0 0" rpy="0 0 0"/>
      <geometry>
        <mesh filename="package://bilkins/meshes/hokuyo.dae"/>
      </geometry>
    </visual>

    <inertial>
      <mass value="1e-5" />
      <origin xyz="0 0 0" rpy="0 0 0"/>
      <inertia ixx="1e-6" ixy="0" ixz="0" iyy="1e-6" iyz="0" izz="1e-6" />
    </inertial>
  </link>

</robot>
