<?xml version="1.0"?>
<robot name="Bilkins">

  <link name="base_link">
    <visual>
      <origin rpy="0.0 0 0" xyz="0 0 0"/>
      <geometry>
        <mesh filename="package://bilkins/meshes/chassis.dae" scale="0.1 0.1 0.1" />
      </geometry>
    </visual>
  </link>

  <link name="rear_axle">
    <visual>
      <geometry>
        <mesh filename="package://bilkins/meshes/rear_axle.dae" scale="0.1 0.1 0.1" />
      </geometry>
      <origin xyz="1.3 0 0.5" />
    </visual>
  </link>

  <link name="front_axle">
    <visual>
      <geometry>
        <mesh filename="package://bilkins/meshes/front_axle.dae" scale="0.1 0.1 0.1" />
      </geometry>
      <origin xyz="-1.3 0 0.5" />
    </visual>
  </link>

  <link name="front_left_wheel">
    <visual>
      <geometry>
        <mesh filename="package://bilkins/meshes/front_left_wheel.dae" scale="0.1 0.1 0.1" />
      </geometry>
    </visual>
  </link>

  <link name="front_right_wheel">
    <visual>
      <geometry>
        <mesh filename="package://bilkins/meshes/front_right_wheel.dae" scale="0.1 0.1 0.1" />
      </geometry>
    </visual>
  </link>

  <joint name="rear_axle_to_chassis" type="continuous">
    <parent link="base_link"/>
    <child link="rear_axle" />
    <axis xyz="0 1 0" />
    <origin xyz="1.3 0 0.5" />
  </joint>

  <joint name="front_axle_to_chassis" type="revolute">
    <axis xyz="0 0 1" />
    <limit effort="1000.0" lower="-0.1" upper="0.1" velocity="0.5"/>
    <origin rpy="0 0 0" xyz="-1.3 0 0.5"/>
    <parent link="base_link"/>
    <child link="front_axle" />
  </joint>

  <joint name="front_left_wheel_to_axle" type="fixed">
    <parent link="front_axle"/>
    <child link="front_left_wheel" />
  </joint>

  <joint name="front_right_wheel_to_axle" type="fixed">
    <parent link="front_axle"/>
    <child link="front_right_wheel" />
  </joint>

</robot>
