<?xml version="1.0"?>
<robot name="Bilkins">


  <link name="base_link">
    <visual>
      <geometry>
        <mesh filename="package://bilkins/meshes/chassis.dae" scale="0.1 0.1 0.1" />
      </geometry>
      <origin rpy="0.0 0 0" xyz="0 0 0"/>
    </visual>
    <collision>
      <geometry>
        <mesh filename="package://bilkins/meshes/chassis.dae" scale="0.1 0.1 0.1" />
      </geometry>
      <origin rpy="0.0 0 0" xyz="0 0 0"/>
    </collision>
    <inertial>
      <mass value="0.2" />
      <inertia ixx="0.4" ixy="0.0" ixz="0.0" iyy="0.4" iyz="0.0" izz="0.2"/>
    </inertial>
  </link>

  <link name="rear_axle">
    <visual>
      <geometry>
        <mesh filename="package://bilkins/meshes/rear_axle.dae" scale="0.1 0.1 0.1" />
      </geometry>
      <origin xyz="-1.3 0 -0.5" />
    </visual>
    <collision>
      <geometry>
        <mesh filename="package://bilkins/meshes/rear_axle.dae" scale="0.1 0.1 0.1" />
      </geometry>
      <origin xyz="-1.3 0 -0.5" />
    </collision>
    <inertial>
      <mass value="0.14" />
      <inertia ixx="0.4" ixy="0.0" ixz="0.0" iyy="0.4" iyz="0.0" izz="0.2"/>
    </inertial>
  </link>

  <link name="front_axle">
    <visual>
      <geometry>
        <mesh filename="package://bilkins/meshes/front_axle.dae" scale="0.1 0.1 0.1" />
      </geometry>
      <origin xyz="1.3 0 -0.5" />
    </visual>
    <collision>
      <geometry>
        <mesh filename="package://bilkins/meshes/front_axle.dae" scale="0.1 0.1 0.1" />
      </geometry>
      <origin xyz="1.3 0 -0.5" />
    </collision>
    <inertial>
      <mass value="0.1" />
      <inertia ixx="0.4" ixy="0.0" ixz="0.0" iyy="0.4" iyz="0.0" izz="0.2"/>
    </inertial>
  </link>

  <link name="front_left_wheel">
    <visual>
      <geometry>
        <mesh filename="package://bilkins/meshes/front_left_wheel.dae" scale="0.1 0.1 0.1" />
      </geometry>
      <origin xyz="1.3 0.9 -0.5" />
    </visual>
    <collision>
      <geometry>
        <mesh filename="package://bilkins/meshes/front_left_wheel.dae" scale="0.1 0.1 0.1" />
      </geometry>
      <origin xyz="1.3 0.9 -0.5" />
    </collision>
    <inertial>
      <mass value="0.02" />
      <inertia ixx="0.4" ixy="0.0" ixz="0.0" iyy="0.4" iyz="0.0" izz="0.2"/>
    </inertial>
  </link>

  <link name="front_right_wheel">
    <visual>
      <geometry>
        <mesh filename="package://bilkins/meshes/front_right_wheel.dae" scale="0.1 0.1 0.1" />
      </geometry>
      <origin xyz="1.3 -0.9 -0.5" />
    </visual>
    <collision>
      <geometry>
        <mesh filename="package://bilkins/meshes/front_right_wheel.dae" scale="0.1 0.1 0.1" />
      </geometry>
      <origin xyz="1.3 -0.9 -0.5" />
    </collision>
    <inertial>
      <mass value="0.02" />
      <inertia ixx="0.4" ixy="0.0" ixz="0.0" iyy="0.4" iyz="0.0" izz="0.2"/>
    </inertial>
  </link>

  <joint name="rear_axle_to_chassis" type="continuous">
    <parent link="base_link"/>
    <child link="rear_axle" />
    <axis xyz="0 1 0" />
    <origin xyz="1.3 0 0.5" />
  </joint>

  <joint name="front_axle_to_chassis" type="revolute">
    <axis xyz="0 0 1" />
    <limit effort="1000.0" lower="-0.1" upper="0.1" velocity="0.5"/>
    <parent link="base_link"/>
    <child link="front_axle" />
    <origin xyz="-1.3 0 0.5" />
  </joint>

  <joint name="front_left_wheel_to_axle" type="continuous">
    <parent link="front_axle"/>
    <child link="front_left_wheel" />
    <axis xyz="0 1 0" />
    <origin xyz="0 -0.9 0" />
  </joint>

  <joint name="front_right_wheel_to_axle" type="continuous">
    <parent link="front_axle"/>
    <child link="front_right_wheel" />
    <axis xyz="0 1 0" />
    <origin xyz="0 0.9 0" />
  </joint>

 <gazebo reference="camera_link">
   <sensor type="camera" name="camera1">
     <update_rate>30.0</update_rate>
     <camera name="head">
       <horizontal_fov>1.3962634</horizontal_fov>
       <image>
         <width>800</width>
         <height>800</height>
         <format>R8G8B8</format>
       </image>
       <clip>
         <near>0.02</near>
         <far>300</far>
       </clip>
       <noise>
         <type>gaussian</type>
         <!-- Noise is sampled independently per pixel on each frame.
              That pixel's noise value is added to each of its color
              channels, which at that point lie in the range [0,1]. -->
         <mean>0.0</mean>
         <stddev>0.007</stddev>
       </noise>
     </camera>
     <plugin name="camera_controller" filename="libgazebo_ros_camera.so">
       <alwaysOn>true</alwaysOn>
       <updateRate>0.0</updateRate>
       <cameraName>rrbot/camera1</cameraName>
       <imageTopicName>image_raw</imageTopicName>
       <cameraInfoTopicName>camera_info</cameraInfoTopicName>
       <frameName>camera_link_optical</frameName>
       <!-- setting hackBaseline to anything but 0.0 will cause a misalignment
           between the gazebo sensor image and the frame it is supposed to
           be attached to -->
       <hackBaseline>0.0</hackBaseline>
       <distortionK1>0.0</distortionK1>
       <distortionK2>0.0</distortionK2>
       <distortionK3>0.0</distortionK3>
       <distortionT1>0.0</distortionT1>
       <distortionT2>0.0</distortionT2>
       <CxPrime>0</CxPrime>
       <Cx>0.0</Cx>
       <Cy>0.0</Cy>
       <focalLength>0.0</focalLength>
     </plugin>
   </sensor>
 </gazebo>

</robot>
